[I 250627 00:00:41 websocket:47] WebSocket opened
[W 250627 01:59:59 smartWebSocketV2:318] Attempting to resubscribe/reconnect (Attempt 1)...
[I 250627 02:00:10 websocket:47] WebSocket opened
[I 250627 17:59:19 websocket:47] WebSocket opened
[W 250627 18:06:47 smartWebSocketV2:318] Attempting to resubscribe/reconnect (Attempt 1)...
[I 250627 18:06:57 websocket:47] WebSocket opened
[E 250627 18:07:56 websocket:55] WebSocket error
    Traceback (most recent call last):
      File "C:\Users\BRIJRAJSINH GOHIL\OneDrive\Desktop\main\Trade_Automation\.venv\Lib\site-packages\websocket\_app.py", line 511, in setSock
        dispatcher.read(self.sock.sock, read, check)
      File "C:\Users\BRIJRAJSINH GOHIL\OneDrive\Desktop\main\Trade_Automation\.venv\Lib\site-packages\websocket\_app.py", line 113, in read
        if not read_callback():
               ^^^^^^^^^^^^^^^
      File "C:\Users\BRIJRAJSINH GOHIL\OneDrive\Desktop\main\Trade_Automation\.venv\Lib\site-packages\websocket\_app.py", line 535, in read
        raise e
      File "C:\Users\BRIJRAJSINH GOHIL\OneDrive\Desktop\main\Trade_Automation\.venv\Lib\site-packages\websocket\_app.py", line 526, in read
        op_code, frame = self.sock.recv_data_frame(True)
                         ^^^^^^^^^^^^^^^^^^^^^^^^^^^^^^^
      File "C:\Users\BRIJRAJSINH GOHIL\OneDrive\Desktop\main\Trade_Automation\.venv\Lib\site-packages\websocket\_core.py", line 437, in recv_data_frame
        frame = self.recv_frame()
                ^^^^^^^^^^^^^^^^^
      File "C:\Users\BRIJRAJSINH GOHIL\OneDrive\Desktop\main\Trade_Automation\.venv\Lib\site-packages\websocket\_core.py", line 478, in recv_frame
        return self.frame_buffer.recv_frame()
               ^^^^^^^^^^^^^^^^^^^^^^^^^^^^^^
      File "C:\Users\BRIJRAJSINH GOHIL\OneDrive\Desktop\main\Trade_Automation\.venv\Lib\site-packages\websocket\_abnf.py", line 363, in recv_frame
        self.recv_header()
      File "C:\Users\BRIJRAJSINH GOHIL\OneDrive\Desktop\main\Trade_Automation\.venv\Lib\site-packages\websocket\_abnf.py", line 319, in recv_header
        header = self.recv_strict(2)
                 ^^^^^^^^^^^^^^^^^^^
      File "C:\Users\BRIJRAJSINH GOHIL\OneDrive\Desktop\main\Trade_Automation\.venv\Lib\site-packages\websocket\_abnf.py", line 398, in recv_strict
        bytes_ = self.recv(min(16384, shortage))
                 ^^^^^^^^^^^^^^^^^^^^^^^^^^^^^^^
      File "C:\Users\BRIJRAJSINH GOHIL\OneDrive\Desktop\main\Trade_Automation\.venv\Lib\site-packages\websocket\_core.py", line 563, in _recv
        return recv(self.sock, bufsize)
               ^^^^^^^^^^^^^^^^^^^^^^^^
      File "C:\Users\BRIJRAJSINH GOHIL\OneDrive\Desktop\main\Trade_Automation\.venv\Lib\site-packages\websocket\_socket.py", line 132, in recv
        raise WebSocketConnectionClosedException("Connection to remote host was lost.")
    websocket._exceptions.WebSocketConnectionClosedException: Connection to remote host was lost.
    
    During handling of the above exception, another exception occurred:
    
    Traceback (most recent call last):
      File "C:\Users\BRIJRAJSINH GOHIL\OneDrive\Desktop\main\Trade_Automation\.venv\Lib\site-packages\websocket\_app.py", line 511, in setSock
        dispatcher.read(self.sock.sock, read, check)
      File "C:\Users\BRIJRAJSINH GOHIL\OneDrive\Desktop\main\Trade_Automation\.venv\Lib\site-packages\websocket\_app.py", line 113, in read
        if not read_callback():
               ^^^^^^^^^^^^^^^
      File "C:\Users\BRIJRAJSINH GOHIL\OneDrive\Desktop\main\Trade_Automation\.venv\Lib\site-packages\websocket\_app.py", line 535, in read
        raise e
      File "C:\Users\BRIJRAJSINH GOHIL\OneDrive\Desktop\main\Trade_Automation\.venv\Lib\site-packages\websocket\_app.py", line 526, in read
        op_code, frame = self.sock.recv_data_frame(True)
                         ^^^^^^^^^^^^^^^^^^^^^^^^^^^^^^^
      File "C:\Users\BRIJRAJSINH GOHIL\OneDrive\Desktop\main\Trade_Automation\.venv\Lib\site-packages\websocket\_core.py", line 437, in recv_data_frame
        frame = self.recv_frame()
                ^^^^^^^^^^^^^^^^^
      File "C:\Users\BRIJRAJSINH GOHIL\OneDrive\Desktop\main\Trade_Automation\.venv\Lib\site-packages\websocket\_core.py", line 478, in recv_frame
        return self.frame_buffer.recv_frame()
               ^^^^^^^^^^^^^^^^^^^^^^^^^^^^^^
      File "C:\Users\BRIJRAJSINH GOHIL\OneDrive\Desktop\main\Trade_Automation\.venv\Lib\site-packages\websocket\_abnf.py", line 363, in recv_frame
        self.recv_header()
      File "C:\Users\BRIJRAJSINH GOHIL\OneDrive\Desktop\main\Trade_Automation\.venv\Lib\site-packages\websocket\_abnf.py", line 319, in recv_header
        header = self.recv_strict(2)
                 ^^^^^^^^^^^^^^^^^^^
      File "C:\Users\BRIJRAJSINH GOHIL\OneDrive\Desktop\main\Trade_Automation\.venv\Lib\site-packages\websocket\_abnf.py", line 398, in recv_strict
        bytes_ = self.recv(min(16384, shortage))
                 ^^^^^^^^^^^^^^^^^^^^^^^^^^^^^^^
      File "C:\Users\BRIJRAJSINH GOHIL\OneDrive\Desktop\main\Trade_Automation\.venv\Lib\site-packages\websocket\_core.py", line 563, in _recv
        return recv(self.sock, bufsize)
               ^^^^^^^^^^^^^^^^^^^^^^^^
      File "C:\Users\BRIJRAJSINH GOHIL\OneDrive\Desktop\main\Trade_Automation\.venv\Lib\site-packages\websocket\_socket.py", line 132, in recv
        raise WebSocketConnectionClosedException("Connection to remote host was lost.")
    websocket._exceptions.WebSocketConnectionClosedException: Connection to remote host was lost.
[W 250627 18:07:56 smartWebSocketV2:342] Connection closed due to max retry attempts reached.
[E 250627 18:07:56 websocket:55] WebSocket error
    Traceback (most recent call last):
      File "C:\Users\BRIJRAJSINH GOHIL\OneDrive\Desktop\main\Trade_Automation\.venv\Lib\site-packages\websocket\_app.py", line 511, in setSock
        dispatcher.read(self.sock.sock, read, check)
      File "C:\Users\BRIJRAJSINH GOHIL\OneDrive\Desktop\main\Trade_Automation\.venv\Lib\site-packages\websocket\_app.py", line 113, in read
        if not read_callback():
               ^^^^^^^^^^^^^^^
      File "C:\Users\BRIJRAJSINH GOHIL\OneDrive\Desktop\main\Trade_Automation\.venv\Lib\site-packages\websocket\_app.py", line 535, in read
        raise e
      File "C:\Users\BRIJRAJSINH GOHIL\OneDrive\Desktop\main\Trade_Automation\.venv\Lib\site-packages\websocket\_app.py", line 526, in read
        op_code, frame = self.sock.recv_data_frame(True)
                         ^^^^^^^^^^^^^^^^^^^^^^^^^^^^^^^
      File "C:\Users\BRIJRAJSINH GOHIL\OneDrive\Desktop\main\Trade_Automation\.venv\Lib\site-packages\websocket\_core.py", line 437, in recv_data_frame
        frame = self.recv_frame()
                ^^^^^^^^^^^^^^^^^
      File "C:\Users\BRIJRAJSINH GOHIL\OneDrive\Desktop\main\Trade_Automation\.venv\Lib\site-packages\websocket\_core.py", line 478, in recv_frame
        return self.frame_buffer.recv_frame()
               ^^^^^^^^^^^^^^^^^^^^^^^^^^^^^^
      File "C:\Users\BRIJRAJSINH GOHIL\OneDrive\Desktop\main\Trade_Automation\.venv\Lib\site-packages\websocket\_abnf.py", line 363, in recv_frame
        self.recv_header()
      File "C:\Users\BRIJRAJSINH GOHIL\OneDrive\Desktop\main\Trade_Automation\.venv\Lib\site-packages\websocket\_abnf.py", line 319, in recv_header
        header = self.recv_strict(2)
                 ^^^^^^^^^^^^^^^^^^^
      File "C:\Users\BRIJRAJSINH GOHIL\OneDrive\Desktop\main\Trade_Automation\.venv\Lib\site-packages\websocket\_abnf.py", line 398, in recv_strict
        bytes_ = self.recv(min(16384, shortage))
                 ^^^^^^^^^^^^^^^^^^^^^^^^^^^^^^^
      File "C:\Users\BRIJRAJSINH GOHIL\OneDrive\Desktop\main\Trade_Automation\.venv\Lib\site-packages\websocket\_core.py", line 563, in _recv
        return recv(self.sock, bufsize)
               ^^^^^^^^^^^^^^^^^^^^^^^^
      File "C:\Users\BRIJRAJSINH GOHIL\OneDrive\Desktop\main\Trade_Automation\.venv\Lib\site-packages\websocket\_socket.py", line 132, in recv
        raise WebSocketConnectionClosedException("Connection to remote host was lost.")
    websocket._exceptions.WebSocketConnectionClosedException: Connection to remote host was lost.
    
    During handling of the above exception, another exception occurred:
    
    Traceback (most recent call last):
      File "C:\Users\BRIJRAJSINH GOHIL\OneDrive\Desktop\main\Trade_Automation\.venv\Lib\site-packages\websocket\_app.py", line 511, in setSock
        dispatcher.read(self.sock.sock, read, check)
      File "C:\Users\BRIJRAJSINH GOHIL\OneDrive\Desktop\main\Trade_Automation\.venv\Lib\site-packages\websocket\_app.py", line 113, in read
        if not read_callback():
               ^^^^^^^^^^^^^^^
      File "C:\Users\BRIJRAJSINH GOHIL\OneDrive\Desktop\main\Trade_Automation\.venv\Lib\site-packages\websocket\_app.py", line 535, in read
        raise e
      File "C:\Users\BRIJRAJSINH GOHIL\OneDrive\Desktop\main\Trade_Automation\.venv\Lib\site-packages\websocket\_app.py", line 526, in read
        op_code, frame = self.sock.recv_data_frame(True)
                         ^^^^^^^^^^^^^^^^^^^^^^^^^^^^^^^
      File "C:\Users\BRIJRAJSINH GOHIL\OneDrive\Desktop\main\Trade_Automation\.venv\Lib\site-packages\websocket\_core.py", line 437, in recv_data_frame
        frame = self.recv_frame()
                ^^^^^^^^^^^^^^^^^
      File "C:\Users\BRIJRAJSINH GOHIL\OneDrive\Desktop\main\Trade_Automation\.venv\Lib\site-packages\websocket\_core.py", line 478, in recv_frame
        return self.frame_buffer.recv_frame()
               ^^^^^^^^^^^^^^^^^^^^^^^^^^^^^^
      File "C:\Users\BRIJRAJSINH GOHIL\OneDrive\Desktop\main\Trade_Automation\.venv\Lib\site-packages\websocket\_abnf.py", line 363, in recv_frame
        self.recv_header()
      File "C:\Users\BRIJRAJSINH GOHIL\OneDrive\Desktop\main\Trade_Automation\.venv\Lib\site-packages\websocket\_abnf.py", line 319, in recv_header
        header = self.recv_strict(2)
                 ^^^^^^^^^^^^^^^^^^^
      File "C:\Users\BRIJRAJSINH GOHIL\OneDrive\Desktop\main\Trade_Automation\.venv\Lib\site-packages\websocket\_abnf.py", line 398, in recv_strict
        bytes_ = self.recv(min(16384, shortage))
                 ^^^^^^^^^^^^^^^^^^^^^^^^^^^^^^^
      File "C:\Users\BRIJRAJSINH GOHIL\OneDrive\Desktop\main\Trade_Automation\.venv\Lib\site-packages\websocket\_core.py", line 563, in _recv
        return recv(self.sock, bufsize)
               ^^^^^^^^^^^^^^^^^^^^^^^^
      File "C:\Users\BRIJRAJSINH GOHIL\OneDrive\Desktop\main\Trade_Automation\.venv\Lib\site-packages\websocket\_socket.py", line 132, in recv
        raise WebSocketConnectionClosedException("Connection to remote host was lost.")
    websocket._exceptions.WebSocketConnectionClosedException: Connection to remote host was lost.
    
    During handling of the above exception, another exception occurred:
    
    Traceback (most recent call last):
      File "C:\Users\BRIJRAJSINH GOHIL\OneDrive\Desktop\main\Trade_Automation\.venv\Lib\site-packages\websocket\_app.py", line 672, in _callback
        callback(self, *args)
    TypeError: SmartWebSocketV2._on_close() takes 2 positional arguments but 4 were given
[W 250627 18:07:56 smartWebSocketV2:342] Connection closed due to max retry attempts reached.
[E 250627 18:07:56 websocket:55] WebSocket error
    Traceback (most recent call last):
      File "C:\Users\BRIJRAJSINH GOHIL\OneDrive\Desktop\main\Trade_Automation\.venv\Lib\site-packages\websocket\_app.py", line 511, in setSock
        dispatcher.read(self.sock.sock, read, check)
      File "C:\Users\BRIJRAJSINH GOHIL\OneDrive\Desktop\main\Trade_Automation\.venv\Lib\site-packages\websocket\_app.py", line 113, in read
        if not read_callback():
               ^^^^^^^^^^^^^^^
      File "C:\Users\BRIJRAJSINH GOHIL\OneDrive\Desktop\main\Trade_Automation\.venv\Lib\site-packages\websocket\_app.py", line 535, in read
        raise e
      File "C:\Users\BRIJRAJSINH GOHIL\OneDrive\Desktop\main\Trade_Automation\.venv\Lib\site-packages\websocket\_app.py", line 526, in read
        op_code, frame = self.sock.recv_data_frame(True)
                         ^^^^^^^^^^^^^^^^^^^^^^^^^^^^^^^
      File "C:\Users\BRIJRAJSINH GOHIL\OneDrive\Desktop\main\Trade_Automation\.venv\Lib\site-packages\websocket\_core.py", line 437, in recv_data_frame
        frame = self.recv_frame()
                ^^^^^^^^^^^^^^^^^
      File "C:\Users\BRIJRAJSINH GOHIL\OneDrive\Desktop\main\Trade_Automation\.venv\Lib\site-packages\websocket\_core.py", line 478, in recv_frame
        return self.frame_buffer.recv_frame()
               ^^^^^^^^^^^^^^^^^^^^^^^^^^^^^^
      File "C:\Users\BRIJRAJSINH GOHIL\OneDrive\Desktop\main\Trade_Automation\.venv\Lib\site-packages\websocket\_abnf.py", line 363, in recv_frame
        self.recv_header()
      File "C:\Users\BRIJRAJSINH GOHIL\OneDrive\Desktop\main\Trade_Automation\.venv\Lib\site-packages\websocket\_abnf.py", line 319, in recv_header
        header = self.recv_strict(2)
                 ^^^^^^^^^^^^^^^^^^^
      File "C:\Users\BRIJRAJSINH GOHIL\OneDrive\Desktop\main\Trade_Automation\.venv\Lib\site-packages\websocket\_abnf.py", line 398, in recv_strict
        bytes_ = self.recv(min(16384, shortage))
                 ^^^^^^^^^^^^^^^^^^^^^^^^^^^^^^^
      File "C:\Users\BRIJRAJSINH GOHIL\OneDrive\Desktop\main\Trade_Automation\.venv\Lib\site-packages\websocket\_core.py", line 563, in _recv
        return recv(self.sock, bufsize)
               ^^^^^^^^^^^^^^^^^^^^^^^^
      File "C:\Users\BRIJRAJSINH GOHIL\OneDrive\Desktop\main\Trade_Automation\.venv\Lib\site-packages\websocket\_socket.py", line 132, in recv
        raise WebSocketConnectionClosedException("Connection to remote host was lost.")
    websocket._exceptions.WebSocketConnectionClosedException: Connection to remote host was lost.
    
    During handling of the above exception, another exception occurred:
    
    Traceback (most recent call last):
      File "C:\Users\BRIJRAJSINH GOHIL\OneDrive\Desktop\main\Trade_Automation\.venv\Lib\site-packages\websocket\_app.py", line 672, in _callback
        callback(self, *args)
    TypeError: SmartWebSocketV2._on_close() takes 2 positional arguments but 4 were given
[W 250627 18:07:56 smartWebSocketV2:342] Connection closed due to max retry attempts reached.
